Workbook

Sheet Start here
A1: FollowThrough: Visibility Autopilot customer workbook
A3: Keep this file blank. For each new customer: File > Make a copy, name it "Autopilot - [business name]", and put its link in the customer list (orders-and-customers, Autopilot customers tab).
A4: The whole customer journey, with the emails to send, is in docs/15-customer-journeys.md. What each plan includes is in docs/01-business-plan.md.
A6: Business details: fill in once, from the customer's welcome email reply. Every listing is copied from here, so they all match exactly. Pick the trade first.
A7: Directories: the list of directories, with the core list for each trade marked Yes. The same for every customer; change it only in the blank copy.
A8: Listing check (all plans): one row per directory. 'Core' fills in by itself from the trade. Core rows: check every month. The others: in the first month, then every 3 months.
A9: Growth and Done-for-you: set up or correct every core listing in the first month. Logins go in your password manager, never in this sheet.
A10: Website check (all plans): one row per problem found. Each month, send the customer the top 5 open ones (Starter) or fix them (Done-for-you).
A11: Each month check, on a phone: speed (pagespeed.web.dev, mobile), Search Console problems, tappable phone number at the top, services and area clear, quote form works, reviews shown, license and insurance mentioned where the state requires it.
A12: Posts (Growth and Done-for-you): one row per weekly Google post. Write a month at a time.
A13: Reviews (Growth and Done-for-you): one row per new review. 'Ask owner first' says Yes for 1 or 2 stars. The date turns yellow when a review has waited 2 working days.
A14: Numbers: one row per month, filled in when you write the report. Type the first month as 2026-11-01; the next months fill in. The grey columns count by themselves.
... A18: Dates: type them as 2026-11-03. Dropdown cells show a small arrow when you click them. Real customer details stay in Google Sheets and never go into the project.

Sheet Business details
A1: Field | B1: Value | C1: Example or note
A2: Business name | C2: Exactly as registered and on their signs, e.g. Acme Roofing LLC or Acme Roofing
A3: Plan | C3: Starter, Growth or Done-for-you
A4: Trade | C4: Pick from the list: it marks the core directories
A5: Owner's name
A6: Phone (the one customers call) | C6: e.g. (512) 555-0134. The same number everywhere
A7: Email (public)
A8: Website | C8: e.g. https://acmeroofing.com
A9: Street address | C9: Leave public listings without it if they work from home
A10: Show the address publicly? | C10: No = service-area business: listings show the area, not the address
A11: City
A12: State | C12: e.g. TX
A13: ZIP code
A14: Service area | C14: Towns or ZIP codes, e.g. Austin, Round Rock, Cedar Park
A15: Hours | C15: e.g. Mon-Fri 7am-6pm, Sat 8am-12pm, Sun closed
A16: Services | C16: The main ones, e.g. roof repair, roof replacement, gutter repair
A17: Short description (up to 250 characters) | C17: For small directories
A18: Long description (up to 750 characters) | C18: For Google, Bing and Yelp. No prices, no links, no claims they can't back up
A19: License numbers | C19: Where the state requires showing them
A20: Year started
A21: Logo (link) | C21: A link to the file in Google Drive
A22: Photos folder (link) | C22: 5-10 photos of their work to start, more each week on Growth
A23: Google profile link
A24: Facebook and Instagram links
A25: Number for confirmation codes | C25: Where directories' codes go by phone or text, and how fast they can pass them on
A26: Website builder or host (Done-for-you) | C26: e.g. Wix, Squarespace, WordPress on Bluehost
A27: Notes

Sheet Directories
A1: Directory | B1: Where to add or claim it | C1: Type | D1: Free to list? | E1: How they confirm the business | F1: Last checked | G1: Notes | H1: HVAC | I1: Plumbing | J1: Roofing | K1: Painting | L1: Handyman | M1: Electrical | N1: Appliance repair | O1: Drywall | P1: Landscaping | Q1: Lawn care | R1: Junk removal | S1: Hauling & transportation | T1: House cleaning | U1: Car detailing | V1: Pressure washing
A2: Google Business Profile | B2: business.google.com | C2: Maps and search | D2: Free | E2: Video call, phone, text, email or postcard, Google chooses | F2: Well known | G2: The most important one. Manager access comes from the owner. | H2: Yes | I2: Yes | J2: Yes | K2: Yes | L2: Yes | M2: Yes | N2: Yes | O2: Yes | P2: Yes | Q2: Yes | R2: Yes | S2: Yes | T2: Yes | U2: Yes | V2: Yes
A3: Bing Places | B3: bingplaces.com | C3: Maps and search | D3: Free | E3: Can import the Google profile; otherwise phone, email or postcard | F3: Well known | G3: Importing from Google is quickest once the Google profile is right. | H3: Yes | I3: Yes | J3: Yes | K3: Yes | L3: Yes | M3: Yes | N3: Yes | O3: Yes | P3: Yes | Q3: Yes | R3: Yes | S3: Yes | T3: Yes | U3: Yes | V3: Yes
A4: Apple Business Connect | B4: businessconnect.apple.com | C4: Maps and search (Apple Maps, Siri) | D4: Free | E4: Phone call or business documents | F4: Well known | H4: Yes | I4: Yes | J4: Yes | K4: Yes | L4: Yes | M4: Yes | N4: Yes | O4: Yes | P4: Yes | Q4: Yes | R4: Yes | S4: Yes | T4: Yes | U4: Yes | V4: Yes
A5: Yelp | B5: biz.yelp.com | C5: Reviews | D5: Free (ads are paid) | E5: Phone call or text | F5: Well known | G5: Yelp calls to sell ads. The owner can say no. | H5: Yes | I5: Yes | J5: Yes | K5: Yes | L5: Yes | M5: Yes | N5: Yes | O5: Yes | P5: Yes | Q5: Yes | R5: Yes | S5: Yes | T5: Yes | U5: Yes | V5: Yes
A6: Facebook page | B6: facebook.com/pages/create | C6: Social | D6: Free | E6: Usually none | F6: Well known | H6: Yes | I6: Yes | J6: Yes | K6: Yes | L6: Yes | M6: Yes | N6: Yes | O6: Yes | P6: Yes | Q6: Yes | R6: Yes | S6: Yes | T6: Yes | U6: Yes | V6: Yes
A7: Nextdoor | B7: business.nextdoor.com | C7: Neighborhood network | D7: Free page | E7: Phone or email | F7: 2026-10-30, web search | G7: The page and posts are free. Some users said in 2026 that a few features moved to a paid plan. | H7: Yes | I7: Yes | J7: Yes | K7: Yes | L7: Yes | M7: Yes | N7: Yes | O7: Yes | P7: Yes | Q7: Yes | R7: Yes | S7: Yes | T7: Yes | U7: Yes | V7: Yes
A8: BBB | B8: bbb.org/get-listed | C8: Reviews and trust | D8: Free listing (accreditation is paid, optional) | E8: BBB staff review the request | F8: Well known | G8: Don't pay for accreditation for the customer. | H8: Yes | I8: Yes | J8: Yes | K8: Yes | L8: Yes | M8: Yes | N8: Yes | O8: Yes | P8: Yes | Q8: Yes | R8: Yes | S8: Yes | T8: Yes | U8: Yes | V8: Yes
A9: Yellow Pages (yp.com) | B9: yellowpages.com, "Free listing" at the bottom | C9: General directory | D9: Free basic listing | E9: Email or phone | F9: 2026-10-30, web search | G9: Run by Thryv, which also feeds Superpages. Thryv may call the owner to sell ads: tell them they can say no. | H9: Yes | I9: Yes | J9: Yes | K9: Yes | L9: Yes | M9: Yes | N9: Yes | O9: Yes | P9: Yes | Q9: Yes | R9: Yes | S9: Yes | T9: Yes | U9: Yes | V9: Yes
A10: Foursquare | B10: foursquare.com, "Claim your business" | C10: Data supplier (feeds other apps and maps) | D10: Free | E10: Phone or email | F10: 2026-10-30, web search | G10: The City Guide app closed in 2024-25, but Foursquare still sends listings to its partners. | H10: Yes | I10: Yes | J10: Yes | K10: Yes | L10: Yes | M10: Yes | N10: Yes | O10: Yes | P10: Yes | Q10: Yes | R10: Yes | S10: Yes | T10: Yes | U10: Yes | V10: Yes
A11: Data Axle Local Listings | B11: data-axle.com/local-listings (formerly Express Update) | C11: Data supplier (feeds other directories) | D11: Free | E11: Their team reviews it. Search first; if not found, use "Contact us" | F11: 2026-10-30, web search | G11: Slow to approve. Check again a month later. | H11: Yes | I11: Yes | J11: Yes | K11: Yes | L11: Yes | M11: Yes | N11: Yes | O11: Yes | P11: Yes | Q11: Yes | R11: Yes | S11: Yes | T11: Yes | U11: Yes | V11: Yes
A12: Angi | B12: angi.com, "Join as a pro" | C12: Home services marketplace | D12: Free profile (leads and ads are paid) | E12: Phone | F12: 2026-10-30, web search | G12: HomeAdvisor is part of Angi now. Never buy leads for the customer. | H12: Yes | I12: Yes | J12: Yes | K12: Yes | L12: Yes | M12: Yes | N12: Yes | O12: Yes | P12: Yes | Q12: Yes | R12: Yes | S12: Yes | T12: Yes | V12: Yes
A13: Thumbtack | B13: thumbtack.com/pro | C13: Services marketplace | D13: Free profile (pays per lead) | E13: Phone or email | F13: Well known | G13: Leads cost money: the owner decides whether to turn them on. | H13: Yes | I13: Yes | J13: Yes | K13: Yes | L13: Yes | M13: Yes | N13: Yes | O13: Yes | P13: Yes | Q13: Yes | R13: Yes | S13: Yes | T13: Yes | U13: Yes | V13: Yes
A14: Houzz | B14: houzz.com/pro | C14: Home projects | D14: Free profile | E14: Email | F14: Well known | G14: Add photos of finished jobs. | H14: Yes | I14: Yes | J14: Yes | K14: Yes | L14: Yes | M14: Yes | O14: Yes | P14: Yes
A15: Porch | B15: porch.com/pro | C15: Home services | D15: Free basic profile | E15: Email or phone | F15: 2026-10-30, web search (sources older) | G15: Check the free profile still exists at first use. | H15: Yes | I15: Yes | J15: Yes | K15: Yes | L15: Yes | M15: Yes | N15: Yes | O15: Yes | P15: Yes | Q15: Yes | R15: Yes | T15: Yes | V15: Yes
A16: HomeGuide | B16: homeguide.com/pro | C16: Home services marketplace | D16: Free profile (pays per lead) | E16: Email | F16: 2026-10-30, web search | H16: Yes | I16: Yes | K16: Yes | L16: Yes | N16: Yes | O16: Yes | P16: Yes | Q16: Yes | R16: Yes | S16: Yes | T16: Yes | V16: Yes
A17: BuildZoom | B17: buildzoom.com, "Contractor sign up" | C17: Licensed contractors | D17: Free to claim (a fee only if hired through them) | E17: Made from state license records; claim it | F17: 2026-10-30, web search | G17: Only for licensed trades. The profile exists already if they hold a state license. | H17: Yes | I17: Yes | J17: Yes | M17: Yes
A18: Bark | B18: bark.com, "Join as a professional" | C18: Services marketplace | D18: Free to list (pays credits per lead) | E18: Email or phone | F18: 2026-10-30, web search | G18: Many leads are poor. The owner decides whether to buy any. | N18: Yes | Q18: Yes | R18: Yes | S18: Yes | T18: Yes | U18: Yes | V18: Yes
A19: uShip | B19: uship.com, "Become a carrier" | C19: Hauling marketplace | D19: Free to join (fee when they win a job) | E19: Email, then their checks | F19: 2026-10-30, web search | S19: Yes
A20: Instagram business profile | B20: instagram.com | C20: Social | D20: Free | E20: None | F20: Well known | G20: Before-and-after photos matter most for detailing. | U20: Yes
A21: Alignable | B21: alignable.com | C21: Local business network | D21: Free | E21: Email | F21: Not checked yet | U21: Yes
A22: Manta | B22: manta.com | C22: General directory | D22: Free basic listing | E22: Email or phone | F22: Not checked yet | U22: Yes
A23: MapQuest | B23: mapquest.com | C23: Maps | D23: Free basic listing, slow; managing it is paid (Yext) | F23: 2026-10-30, web search | G23: Check only.
A24: Waze | B24: waze.com | C24: Maps | D24: Free place edits; ads are paid | F24: Not checked yet | G24: Check only.
A25: Superpages | B25: superpages.com | C25: General directory | D25: Fed by the Yellow Pages listing | F25: Not checked yet | G25: Check only: fix it through Yellow Pages.
A26: Yahoo local results | B26: search.yahoo.com | C26: Search | D26: Shows data from Bing and Yelp | F26: Not checked yet | G26: Check only: fix it through Bing and Yelp.
A27: LinkedIn company page | B27: linkedin.com/company/setup/new | C27: Social | D27: Free | F27: Well known
A28: Chamber of Commerce (chamberofcommerce.com) | B28: chamberofcommerce.com | C28: General directory | D28: Free basic listing | F28: Not checked yet | G28: Not the same as their town's chamber.
A29: Hotfrog | B29: hotfrog.com | C29: General directory | D29: Free | F29: Not checked yet
A30: Brownbook | B30: brownbook.net | C30: General directory | D30: Free | F30: Not checked yet
A31: EZlocal | B31: ezlocal.com | C31: General directory | D31: Free | F31: Not checked yet
A32: ShowMeLocal | B32: showmelocal.com | C32: General directory | D32: Free | F32: Not checked yet
A33: Cylex | B33: cylex.us.com | C33: General directory | D33: Free | F33: Not checked yet
A34: MerchantCircle | B34: merchantcircle.com | C34: General directory | D34: Free | F34: Not checked yet
A35: Hub.biz | B35: hub.biz | C35: General directory | D35: Free | F35: Not checked yet
A36: Opendi | B36: opendi.us | C36: General directory | D36: Free | F36: Not checked yet
A37: Trustpilot | B37: business.trustpilot.com | C37: Reviews | D37: Free basic account | F37: Not checked yet
A38: Birdeye | B38: birdeye.com | C38: Reviews | D38: Free directory profile | F38: Not checked yet
A39: Expertise.com | B39: expertise.com | C39: "Best of" lists | D39: They choose who's listed | F39: Not checked yet | G39: Check whether they're listed; you can't sign up.
A40: Local Home Service Pros | B40: localhomeservicepros.com | C40: Home services directory | D40: Free | F40: Not checked yet
...

Sheet Listing check
A1: Directory | B1: Core for this business | C1: How often to check | D1: Status | E1: What's wrong | F1: Link to their listing | G1: Login in password manager | H1: Last checked | I1: Fixed on | J1: Notes
A2: =Directories!A2 | B2: =IF('Business details'!$B$4="","",IF(INDEX(Directories!$H2:$V2,MATCH('Business details'!$B$4,Directories!$H$1:$V$1,0))="Yes","Yes","No")) | C2: =IF(B2="","",IF(B2="Yes","Every month","Every 3 months"))
A3: =Directories!A3 | B3: =IF('Business details'!$B$4="","",IF(INDEX(Directories!$H3:$V3,MATCH('Business details'!$B$4,Directories!$H$1:$V$1,0))="Yes","Yes","No")) | C3: =IF(B3="","",IF(B3="Yes","Every month","Every 3 months"))
A4: =Directories!A4 | B4: =IF('Business details'!$B$4="","",IF(INDEX(Directories!$H4:$V4,MATCH('Business details'!$B$4,Directories!$H$1:$V$1,0))="Yes","Yes","No")) | C4: =IF(B4="","",IF(B4="Yes","Every month","Every 3 months"))
A5: =Directories!A5 | B5: =IF('Business details'!$B$4="","",IF(INDEX(Directories!$H5:$V5,MATCH('Business details'!$B$4,Directories!$H$1:$V$1,0))="Yes","Yes","No")) | C5: =IF(B5="","",IF(B5="Yes","Every month","Every 3 months"))
A6: =Directories!A6 | B6: =IF('Business details'!$B$4="","",IF(INDEX(Directories!$H6:$V6,MATCH('Business details'!$B$4,Directories!$H$1:$V$1,0))="Yes","Yes","No")) | C6: =IF(B6="","",IF(B6="Yes","Every month","Every 3 months"))
A7: =Directories!A7 | B7: =IF('Business details'!$B$4="","",IF(INDEX(Directories!$H7:$V7,MATCH('Business details'!$B$4,Directories!$H$1:$V$1,0))="Yes","Yes","No")) | C7: =IF(B7="","",IF(B7="Yes","Every month","Every 3 months"))
A8: =Directories!A8 | B8: =IF('Business details'!$B$4="","",IF(INDEX(Directories!$H8:$V8,MATCH('Business details'!$B$4,Directories!$H$1:$V$1,0))="Yes","Yes","No")) | C8: =IF(B8="","",IF(B8="Yes","Every month","Every 3 months"))
A9: =Directories!A9 | B9: =IF('Business details'!$B$4="","",IF(INDEX(Directories!$H9:$V9,MATCH('Business details'!$B$4,Directories!$H$1:$V$1,0))="Yes","Yes","No")) | C9: =IF(B9="","",IF(B9="Yes","Every month","Every 3 months"))
A10: =Directories!A10 | B10: =IF('Business details'!$B$4="","",IF(INDEX(Directories!$H10:$V10,MATCH('Business details'!$B$4,Directories!$H$1:$V$1,0))="Yes","Yes","No")) | C10: =IF(B10="","",IF(B10="Yes","Every month","Every 3 months"))
A11: =Directories!A11 | B11: =IF('Business details'!$B$4="","",IF(INDEX(Directories!$H11:$V11,MATCH('Business details'!$B$4,Directories!$H$1:$V$1,0))="Yes","Yes","No")) | C11: =IF(B11="","",IF(B11="Yes","Every month","Every 3 months"))
A12: =Directories!A12 | B12: =IF('Business details'!$B$4="","",IF(INDEX(Directories!$H12:$V12,MATCH('Business details'!$B$4,Directories!$H$1:$V$1,0))="Yes","Yes","No")) | C12: =IF(B12="","",IF(B12="Yes","Every month","Every 3 months"))
A13: =Directories!A13 | B13: =IF('Business details'!$B$4="","",IF(INDEX(Directories!$H13:$V13,MATCH('Business details'!$B$4,Directories!$H$1:$V$1,0))="Yes","Yes","No")) | C13: =IF(B13="","",IF(B13="Yes","Every month","Every 3 months"))
... A50: =Directories!A50 | B50: =IF('Business details'!$B$4="","",IF(INDEX(Directories!$H50:$V50,MATCH('Business details'!$B$4,Directories!$H$1:$V$1,0))="Yes","Yes","No")) | C50: =IF(B50="","",IF(B50="Yes","Every month","Every 3 months"))

Sheet Website check
A1: Found on | B1: Area | C1: Problem | D1: Priority | E1: How to fix (one sentence) | F1: Who fixes it | G1: Status | H1: Fixed on | I1: Notes

Sheet Posts
A1: Week of | B1: Type | C1: Post text | D1: Photo | E1: Owner approved (offers) | F1: Scheduled for | G1: Published on | H1: Notes

Sheet Reviews
A1: Review date | B1: Reviewer | C1: Stars | D1: Alert sent to owner | E1: Ask owner first? | F1: Reply | G1: Replied on | H1: Notes
E2: =IF(C2="","",IF(C2<=2,"Yes","No"))
E3: =IF(C3="","",IF(C3<=2,"Yes","No"))
E4: =IF(C4="","",IF(C4<=2,"Yes","No"))
E5: =IF(C5="","",IF(C5<=2,"Yes","No"))
E6: =IF(C6="","",IF(C6<=2,"Yes","No"))
E7: =IF(C7="","",IF(C7<=2,"Yes","No"))
E8: =IF(C8="","",IF(C8<=2,"Yes","No"))
E9: =IF(C9="","",IF(C9<=2,"Yes","No"))
E10: =IF(C10="","",IF(C10<=2,"Yes","No"))
E11: =IF(C11="","",IF(C11<=2,"Yes","No"))
E12: =IF(C12="","",IF(C12<=2,"Yes","No"))
E13: =IF(C13="","",IF(C13<=2,"Yes","No"))
... E501: =IF(C501="","",IF(C501<=2,"Yes","No"))

Sheet Numbers
A1: Month | B1: Calls from your Google profile | C1: Website visits from your Google profile | D1: Direction requests | E1: New reviews | F1: Average rating | G1: Listings correct | H1: Listings that matter for your trade | I1: Website speed on a phone (out of 100) | J1: Website problems fixed | K1: Google posts published | L1: Reviews replied to | M1: Listings fixed
J2: =IF($A2="","",COUNTIFS('Website check'!$H$2:$H$501,">="&$A2,'Website check'!$H$2:$H$501,"<"&EDATE($A2,1))) | K2: =IF($A2="","",COUNTIFS(Posts!$G$2:$G$501,">="&$A2,Posts!$G$2:$G$501,"<"&EDATE($A2,1))) | L2: =IF($A2="","",COUNTIFS(Reviews!$G$2:$G$501,">="&$A2,Reviews!$G$2:$G$501,"<"&EDATE($A2,1))) | M2: =IF($A2="","",COUNTIFS('Listing check'!$I$2:$I$50,">="&$A2,'Listing check'!$I$2:$I$50,"<"&EDATE($A2,1)))
A3: =IF($A2="","",EDATE($A2,1)) | J3: =IF($A3="","",COUNTIFS('Website check'!$H$2:$H$501,">="&$A3,'Website check'!$H$2:$H$501,"<"&EDATE($A3,1))) | K3: =IF($A3="","",COUNTIFS(Posts!$G$2:$G$501,">="&$A3,Posts!$G$2:$G$501,"<"&EDATE($A3,1))) | L3: =IF($A3="","",COUNTIFS(Reviews!$G$2:$G$501,">="&$A3,Reviews!$G$2:$G$501,"<"&EDATE($A3,1))) | M3: =IF($A3="","",COUNTIFS('Listing check'!$I$2:$I$50,">="&$A3,'Listing check'!$I$2:$I$50,"<"&EDATE($A3,1)))
A4: =IF($A3="","",EDATE($A3,1)) | J4: =IF($A4="","",COUNTIFS('Website check'!$H$2:$H$501,">="&$A4,'Website check'!$H$2:$H$501,"<"&EDATE($A4,1))) | K4: =IF($A4="","",COUNTIFS(Posts!$G$2:$G$501,">="&$A4,Posts!$G$2:$G$501,"<"&EDATE($A4,1))) | L4: =IF($A4="","",COUNTIFS(Reviews!$G$2:$G$501,">="&$A4,Reviews!$G$2:$G$501,"<"&EDATE($A4,1))) | M4: =IF($A4="","",COUNTIFS('Listing check'!$I$2:$I$50,">="&$A4,'Listing check'!$I$2:$I$50,"<"&EDATE($A4,1)))
A5: =IF($A4="","",EDATE($A4,1)) | J5: =IF($A5="","",COUNTIFS('Website check'!$H$2:$H$501,">="&$A5,'Website check'!$H$2:$H$501,"<"&EDATE($A5,1))) | K5: =IF($A5="","",COUNTIFS(Posts!$G$2:$G$501,">="&$A5,Posts!$G$2:$G$501,"<"&EDATE($A5,1))) | L5: =IF($A5="","",COUNTIFS(Reviews!$G$2:$G$501,">="&$A5,Reviews!$G$2:$G$501,"<"&EDATE($A5,1))) | M5: =IF($A5="","",COUNTIFS('Listing check'!$I$2:$I$50,">="&$A5,'Listing check'!$I$2:$I$50,"<"&EDATE($A5,1)))
A6: =IF($A5="","",EDATE($A5,1)) | J6: =IF($A6="","",COUNTIFS('Website check'!$H$2:$H$501,">="&$A6,'Website check'!$H$2:$H$501,"<"&EDATE($A6,1))) | K6: =IF($A6="","",COUNTIFS(Posts!$G$2:$G$501,">="&$A6,Posts!$G$2:$G$501,"<"&EDATE($A6,1))) | L6: =IF($A6="","",COUNTIFS(Reviews!$G$2:$G$501,">="&$A6,Reviews!$G$2:$G$501,"<"&EDATE($A6,1))) | M6: =IF($A6="","",COUNTIFS('Listing check'!$I$2:$I$50,">="&$A6,'Listing check'!$I$2:$I$50,"<"&EDATE($A6,1)))
A7: =IF($A6="","",EDATE($A6,1)) | J7: =IF($A7="","",COUNTIFS('Website check'!$H$2:$H$501,">="&$A7,'Website check'!$H$2:$H$501,"<"&EDATE($A7,1))) | K7: =IF($A7="","",COUNTIFS(Posts!$G$2:$G$501,">="&$A7,Posts!$G$2:$G$501,"<"&EDATE($A7,1))) | L7: =IF($A7="","",COUNTIFS(Reviews!$G$2:$G$501,">="&$A7,Reviews!$G$2:$G$501,"<"&EDATE($A7,1))) | M7: =IF($A7="","",COUNTIFS('Listing check'!$I$2:$I$50,">="&$A7,'Listing check'!$I$2:$I$50,"<"&EDATE($A7,1)))
A8: =IF($A7="","",EDATE($A7,1)) | J8: =IF($A8="","",COUNTIFS('Website check'!$H$2:$H$501,">="&$A8,'Website check'!$H$2:$H$501,"<"&EDATE($A8,1))) | K8: =IF($A8="","",COUNTIFS(Posts!$G$2:$G$501,">="&$A8,Posts!$G$2:$G$501,"<"&EDATE($A8,1))) | L8: =IF($A8="","",COUNTIFS(Reviews!$G$2:$G$501,">="&$A8,Reviews!$G$2:$G$501,"<"&EDATE($A8,1))) | M8: =IF($A8="","",COUNTIFS('Listing check'!$I$2:$I$50,">="&$A8,'Listing check'!$I$2:$I$50,"<"&EDATE($A8,1)))
A9: =IF($A8="","",EDATE($A8,1)) | J9: =IF($A9="","",COUNTIFS('Website check'!$H$2:$H$501,">="&$A9,'Website check'!$H$2:$H$501,"<"&EDATE($A9,1))) | K9: =IF($A9="","",COUNTIFS(Posts!$G$2:$G$501,">="&$A9,Posts!$G$2:$G$501,"<"&EDATE($A9,1))) | L9: =IF($A9="","",COUNTIFS(Reviews!$G$2:$G$501,">="&$A9,Reviews!$G$2:$G$501,"<"&EDATE($A9,1))) | M9: =IF($A9="","",COUNTIFS('Listing check'!$I$2:$I$50,">="&$A9,'Listing check'!$I$2:$I$50,"<"&EDATE($A9,1)))
A10: =IF($A9="","",EDATE($A9,1)) | J10: =IF($A10="","",COUNTIFS('Website check'!$H$2:$H$501,">="&$A10,'Website check'!$H$2:$H$501,"<"&EDATE($A10,1))) | K10: =IF($A10="","",COUNTIFS(Posts!$G$2:$G$501,">="&$A10,Posts!$G$2:$G$501,"<"&EDATE($A10,1))) | L10: =IF($A10="","",COUNTIFS(Reviews!$G$2:$G$501,">="&$A10,Reviews!$G$2:$G$501,"<"&EDATE($A10,1))) | M10: =IF($A10="","",COUNTIFS('Listing check'!$I$2:$I$50,">="&$A10,'Listing check'!$I$2:$I$50,"<"&EDATE($A10,1)))
A11: =IF($A10="","",EDATE($A10,1)) | J11: =IF($A11="","",COUNTIFS('Website check'!$H$2:$H$501,">="&$A11,'Website check'!$H$2:$H$501,"<"&EDATE($A11,1))) | K11: =IF($A11="","",COUNTIFS(Posts!$G$2:$G$501,">="&$A11,Posts!$G$2:$G$501,"<"&EDATE($A11,1))) | L11: =IF($A11="","",COUNTIFS(Reviews!$G$2:$G$501,">="&$A11,Reviews!$G$2:$G$501,"<"&EDATE($A11,1))) | M11: =IF($A11="","",COUNTIFS('Listing check'!$I$2:$I$50,">="&$A11,'Listing check'!$I$2:$I$50,"<"&EDATE($A11,1)))
A12: =IF($A11="","",EDATE($A11,1)) | J12: =IF($A12="","",COUNTIFS('Website check'!$H$2:$H$501,">="&$A12,'Website check'!$H$2:$H$501,"<"&EDATE($A12,1))) | K12: =IF($A12="","",COUNTIFS(Posts!$G$2:$G$501,">="&$A12,Posts!$G$2:$G$501,"<"&EDATE($A12,1))) | L12: =IF($A12="","",COUNTIFS(Reviews!$G$2:$G$501,">="&$A12,Reviews!$G$2:$G$501,"<"&EDATE($A12,1))) | M12: =IF($A12="","",COUNTIFS('Listing check'!$I$2:$I$50,">="&$A12,'Listing check'!$I$2:$I$50,"<"&EDATE($A12,1)))
A13: =IF($A12="","",EDATE($A12,1)) | J13: =IF($A13="","",COUNTIFS('Website check'!$H$2:$H$501,">="&$A13,'Website check'!$H$2:$H$501,"<"&EDATE($A13,1))) | K13: =IF($A13="","",COUNTIFS(Posts!$G$2:$G$501,">="&$A13,Posts!$G$2:$G$501,"<"&EDATE($A13,1))) | L13: =IF($A13="","",COUNTIFS(Reviews!$G$2:$G$501,">="&$A13,Reviews!$G$2:$G$501,"<"&EDATE($A13,1))) | M13: =IF($A13="","",COUNTIFS('Listing check'!$I$2:$I$50,">="&$A13,'Listing check'!$I$2:$I$50,"<"&EDATE($A13,1)))
A14: =IF($A13="","",EDATE($A13,1)) | J14: =IF($A14="","",COUNTIFS('Website check'!$H$2:$H$501,">="&$A14,'Website check'!$H$2:$H$501,"<"&EDATE($A14,1))) | K14: =IF($A14="","",COUNTIFS(Posts!$G$2:$G$501,">="&$A14,Posts!$G$2:$G$501,"<"&EDATE($A14,1))) | L14: =IF($A14="","",COUNTIFS(Reviews!$G$2:$G$501,">="&$A14,Reviews!$G$2:$G$501,"<"&EDATE($A14,1))) | M14: =IF($A14="","",COUNTIFS('Listing check'!$I$2:$I$50,">="&$A14,'Listing check'!$I$2:$I$50,"<"&EDATE($A14,1)))
... A37: =IF($A36="","",EDATE($A36,1)) | J37: =IF($A37="","",COUNTIFS('Website check'!$H$2:$H$501,">="&$A37,'Website check'!$H$2:$H$501,"<"&EDATE($A37,1))) | K37: =IF($A37="","",COUNTIFS(Posts!$G$2:$G$501,">="&$A37,Posts!$G$2:$G$501,"<"&EDATE($A37,1))) | L37: =IF($A37="","",COUNTIFS(Reviews!$G$2:$G$501,">="&$A37,Reviews!$G$2:$G$501,"<"&EDATE($A37,1))) | M37: =IF($A37="","",COUNTIFS('Listing check'!$I$2:$I$50,">="&$A37,'Listing check'!$I$2:$I$50,"<"&EDATE($A37,1)))

Sheet Report
A1: Monthly report
A2: Business | B2: ='Business details'!B2
A3: Month (type e.g. 2026-11-01)
A5: What | B5: This month | C5: Last month | D5: Change
A6: Calls from your Google profile | B6: =IF($B$3="","",IFERROR(IF(INDEX(Numbers!$B$2:$M$37,MATCH($B$3,Numbers!$A$2:$A$37,0),1)="","",INDEX(Numbers!$B$2:$M$37,MATCH($B$3,Numbers!$A$2:$A$37,0),1)),"")) | C6: =IF($B$3="","",IFERROR(IF(INDEX(Numbers!$B$2:$M$37,MATCH(EDATE($B$3,-1),Numbers!$A$2:$A$37,0),1)="","",INDEX(Numbers!$B$2:$M$37,MATCH(EDATE($B$3,-1),Numbers!$A$2:$A$37,0),1)),"")) | D6: =IF(OR(B6="",C6=""),"",B6-C6)
A7: Website visits from your Google profile | B7: =IF($B$3="","",IFERROR(IF(INDEX(Numbers!$B$2:$M$37,MATCH($B$3,Numbers!$A$2:$A$37,0),2)="","",INDEX(Numbers!$B$2:$M$37,MATCH($B$3,Numbers!$A$2:$A$37,0),2)),"")) | C7: =IF($B$3="","",IFERROR(IF(INDEX(Numbers!$B$2:$M$37,MATCH(EDATE($B$3,-1),Numbers!$A$2:$A$37,0),2)="","",INDEX(Numbers!$B$2:$M$37,MATCH(EDATE($B$3,-1),Numbers!$A$2:$A$37,0),2)),"")) | D7: =IF(OR(B7="",C7=""),"",B7-C7)
A8: Direction requests | B8: =IF($B$3="","",IFERROR(IF(INDEX(Numbers!$B$2:$M$37,MATCH($B$3,Numbers!$A$2:$A$37,0),3)="","",INDEX(Numbers!$B$2:$M$37,MATCH($B$3,Numbers!$A$2:$A$37,0),3)),"")) | C8: =IF($B$3="","",IFERROR(IF(INDEX(Numbers!$B$2:$M$37,MATCH(EDATE($B$3,-1),Numbers!$A$2:$A$37,0),3)="","",INDEX(Numbers!$B$2:$M$37,MATCH(EDATE($B$3,-1),Numbers!$A$2:$A$37,0),3)),"")) | D8: =IF(OR(B8="",C8=""),"",B8-C8)
A9: New reviews | B9: =IF($B$3="","",IFERROR(IF(INDEX(Numbers!$B$2:$M$37,MATCH($B$3,Numbers!$A$2:$A$37,0),4)="","",INDEX(Numbers!$B$2:$M$37,MATCH($B$3,Numbers!$A$2:$A$37,0),4)),"")) | C9: =IF($B$3="","",IFERROR(IF(INDEX(Numbers!$B$2:$M$37,MATCH(EDATE($B$3,-1),Numbers!$A$2:$A$37,0),4)="","",INDEX(Numbers!$B$2:$M$37,MATCH(EDATE($B$3,-1),Numbers!$A$2:$A$37,0),4)),"")) | D9: =IF(OR(B9="",C9=""),"",B9-C9)
A10: Average rating | B10: =IF($B$3="","",IFERROR(IF(INDEX(Numbers!$B$2:$M$37,MATCH($B$3,Numbers!$A$2:$A$37,0),5)="","",INDEX(Numbers!$B$2:$M$37,MATCH($B$3,Numbers!$A$2:$A$37,0),5)),"")) | C10: =IF($B$3="","",IFERROR(IF(INDEX(Numbers!$B$2:$M$37,MATCH(EDATE($B$3,-1),Numbers!$A$2:$A$37,0),5)="","",INDEX(Numbers!$B$2:$M$37,MATCH(EDATE($B$3,-1),Numbers!$A$2:$A$37,0),5)),"")) | D10: =IF(OR(B10="",C10=""),"",B10-C10)
A11: Listings correct | B11: =IF($B$3="","",IFERROR(IF(INDEX(Numbers!$B$2:$M$37,MATCH($B$3,Numbers!$A$2:$A$37,0),6)="","",INDEX(Numbers!$B$2:$M$37,MATCH($B$3,Numbers!$A$2:$A$37,0),6)),"")) | C11: =IF($B$3="","",IFERROR(IF(INDEX(Numbers!$B$2:$M$37,MATCH(EDATE($B$3,-1),Numbers!$A$2:$A$37,0),6)="","",INDEX(Numbers!$B$2:$M$37,MATCH(EDATE($B$3,-1),Numbers!$A$2:$A$37,0),6)),"")) | D11: =IF(OR(B11="",C11=""),"",B11-C11)
A12: Listings that matter for your trade | B12: =IF($B$3="","",IFERROR(IF(INDEX(Numbers!$B$2:$M$37,MATCH($B$3,Numbers!$A$2:$A$37,0),7)="","",INDEX(Numbers!$B$2:$M$37,MATCH($B$3,Numbers!$A$2:$A$37,0),7)),"")) | C12: =IF($B$3="","",IFERROR(IF(INDEX(Numbers!$B$2:$M$37,MATCH(EDATE($B$3,-1),Numbers!$A$2:$A$37,0),7)="","",INDEX(Numbers!$B$2:$M$37,MATCH(EDATE($B$3,-1),Numbers!$A$2:$A$37,0),7)),"")) | D12: =IF(OR(B12="",C12=""),"",B12-C12)
A13: Website speed on a phone (out of 100) | B13: =IF($B$3="","",IFERROR(IF(INDEX(Numbers!$B$2:$M$37,MATCH($B$3,Numbers!$A$2:$A$37,0),8)="","",INDEX(Numbers!$B$2:$M$37,MATCH($B$3,Numbers!$A$2:$A$37,0),8)),"")) | C13: =IF($B$3="","",IFERROR(IF(INDEX(Numbers!$B$2:$M$37,MATCH(EDATE($B$3,-1),Numbers!$A$2:$A$37,0),8)="","",INDEX(Numbers!$B$2:$M$37,MATCH(EDATE($B$3,-1),Numbers!$A$2:$A$37,0),8)),"")) | D13: =IF(OR(B13="",C13=""),"",B13-C13)
A14: Website problems fixed | B14: =IF($B$3="","",IFERROR(IF(INDEX(Numbers!$B$2:$M$37,MATCH($B$3,Numbers!$A$2:$A$37,0),9)="","",INDEX(Numbers!$B$2:$M$37,MATCH($B$3,Numbers!$A$2:$A$37,0),9)),"")) | C14: =IF($B$3="","",IFERROR(IF(INDEX(Numbers!$B$2:$M$37,MATCH(EDATE($B$3,-1),Numbers!$A$2:$A$37,0),9)="","",INDEX(Numbers!$B$2:$M$37,MATCH(EDATE($B$3,-1),Numbers!$A$2:$A$37,0),9)),"")) | D14: =IF(OR(B14="",C14=""),"",B14-C14)
A15: Google posts published | B15: =IF($B$3="","",IFERROR(IF(INDEX(Numbers!$B$2:$M$37,MATCH($B$3,Numbers!$A$2:$A$37,0),10)="","",INDEX(Numbers!$B$2:$M$37,MATCH($B$3,Numbers!$A$2:$A$37,0),10)),"")) | C15: =IF($B$3="","",IFERROR(IF(INDEX(Numbers!$B$2:$M$37,MATCH(EDATE($B$3,-1),Numbers!$A$2:$A$37,0),10)="","",INDEX(Numbers!$B$2:$M$37,MATCH(EDATE($B$3,-1),Numbers!$A$2:$A$37,0),10)),"")) | D15: =IF(OR(B15="",C15=""),"",B15-C15)
A16: Reviews replied to | B16: =IF($B$3="","",IFERROR(IF(INDEX(Numbers!$B$2:$M$37,MATCH($B$3,Numbers!$A$2:$A$37,0),11)="","",INDEX(Numbers!$B$2:$M$37,MATCH($B$3,Numbers!$A$2:$A$37,0),11)),"")) | C16: =IF($B$3="","",IFERROR(IF(INDEX(Numbers!$B$2:$M$37,MATCH(EDATE($B$3,-1),Numbers!$A$2:$A$37,0),11)="","",INDEX(Numbers!$B$2:$M$37,MATCH(EDATE($B$3,-1),Numbers!$A$2:$A$37,0),11)),"")) | D16: =IF(OR(B16="",C16=""),"",B16-C16)
A17: Listings fixed | B17: =IF($B$3="","",IFERROR(IF(INDEX(Numbers!$B$2:$M$37,MATCH($B$3,Numbers!$A$2:$A$37,0),12)="","",INDEX(Numbers!$B$2:$M$37,MATCH($B$3,Numbers!$A$2:$A$37,0),12)),"")) | C17: =IF($B$3="","",IFERROR(IF(INDEX(Numbers!$B$2:$M$37,MATCH(EDATE($B$3,-1),Numbers!$A$2:$A$37,0),12)="","",INDEX(Numbers!$B$2:$M$37,MATCH(EDATE($B$3,-1),Numbers!$A$2:$A$37,0),12)),"")) | D17: =IF(OR(B17="",C17=""),"",B17-C17)
A19: What I did this month
A20: Top 3 for next month
A21: What I need from you
A23: Right now, for this month's Numbers row (not part of the report):
A24: Core listings correct | B24: =COUNTIFS('Listing check'!$B$2:$B$50,"Yes",'Listing check'!$D$2:$D$50,"Correct")
A25: Core listings in total | B25: =COUNTIF('Listing check'!$B$2:$B$50,"Yes")
A26: Website problems still open | B26: =COUNTIF('Website check'!$G$2:$G$501,"Open")

Sheet Calls
A1: Date | B1: Zoom or Meet link | C1: Top 3 fixes agreed | D1: Post themes for next month | E1: Jobs they want more of | F1: Notes
